Workbook

Sheet 0_README
A1: DAY 22 — MONETIZATION MODEL
A2: AI Pricing · GTM · Evidence — AI-IN-ACTION Track 1
A4: QUY ƯỚC MÀU — CHỈ ĐIỀN VÀO Ô MÀU VÀNG
A5: Ô VÀNG, chữ xanh dương | B5: Ô bạn phải điền
A6: Ô XÁM, chữ đen | B6: Công thức tự tính — KHÔNG SỬA
A7: Chữ xanh lá | B7: Link sang tab khác
A8: Ô XÁM đậm nhạt | B8: Bảng tham chiếu, chỉ đọc
A10: THỨ TỰ LÀM — 6 TRẠM, 120 PHÚT
A11: Trạm 1 · 15' | B11: Ngân sách khách & định nghĩa Job → điền S1–S2 của tab 1_Cost_Job
A12: Trạm 2 · 20' | B12: Value Metric → tab 3_Value_Metric
A13: Trạm 3 · 30' | B13: Cost/Job, giá sàn & giá trần → tab 1_Cost_Job (S3–S8) rồi 2_Pricing
A14: Trạm 4 · 20' | B14: Kênh phân phối & Affordability Test → tab 4_Channel_Fit
A15: Trạm 5 · 15' | B15: Pain Moment & 90-Day Plan → tab 5_90Day_Plan
A16: Trạm 6 · 20' | B16: Evidence Pack & ráp One-Pager → tab 5_90Day_Plan + file .docx
A18: 3 QUY TẮC KHÔNG ĐƯỢC PHÁ
A19: 1. Chia cho số job HOÀN THÀNH, không phải số job đã thử.
A20: 2. HITL và Retry không được để 0 nếu không có lý do viết ra được.
A21: 3. Mọi con số giá API phải có NGÀY kiểm tra (xem tab 6_Benchmarks).
A23: Giá tham chiếu trong workbook này được chốt ngày 26/08/2026. Nhiều mức giá là KHUYẾN MẠI CÓ HẠN.
A24: Bạn PHẢI tự mở lại trang giá của nhà cung cấp và cập nhật — đây là một phần của bài tập.
A25: V5 RESEARCH SIMULATION · No MVP / customer interviews / payment or eval. 11_Simulations & 12_Research_Sources contain scenarios and source trace; DO NOT report these as observed evidence.
A28: OWNER / Người làm bài: Bùi Thị Ngọc Trân · dự án cá nhân. Mọi vai trò kỹ thuật/QA/Procurement trong kế hoạch đều do chủ dự án quản lý; chưa có nhân viên hay pilot.
A29: Dữ liệu giả định (containment 65%, CAC PLG $80, volume 1000 ticket, pricing) KHÔNG là kết quả thực nghiệm. Giá API 08/10/2026 cần tái xác minh khi nộp.

Sheet 1_Cost_Job
A1: TAB 1 — COST/JOB CALCULATOR
A2: Trạm 1 (S1–S2) và Trạm 3 (S3–S8). Chỉ điền ô vàng.
A4: S1. ĐỊNH NGHĨA JOB
A5: 1 job của bạn là gì? | B5: 1 ticket đúng chính sách, không chuyển người, không mở lại trong 24h (giả định đo) | D5: Phải là thứ KHÁCH coi là giá trị — không phải '1 request'
A6: Biến thể HITL: A hay B? | B6: A | D6: A = khách tự xử lý ca escalate · B = BẠN chịu (outcome/managed)
A8: S2. KHỐI LƯỢNG
A9: Số job THỬ / tháng | B9: 1000 | C9: job | D9: GIẢ ĐỊNH: 1 shop mục tiêu, chưa đo
A10: Containment rate (AI tự làm xong) | B10: 0.65 | D10: 65% GIẢ ĐỊNH, KHÔNG phải eval
A11: → Số job HOÀN THÀNH / tháng | B11: =B9*B10 -> 650 | C11: job | D11: MẪU SỐ của Cost/Job
A12: → Số job KHÔNG xong / tháng | B12: =B9-B11 -> 350 | C12: job | D12: Số ca phải escalate
A14: S3. API — LLM
A15: Giá input ($ / 1M token) | B15: 1 | D15: Claude Haiku 4.5 — xem tab 6_Benchmarks
A16: Giá output ($ / 1M token) | B16: 5
A17: Giá cache WRITE ($ / 1M token) | B17: 1.25 | D17: Anthropic 5-phút = 1,25× input
A18: Giá cache READ ($ / 1M token) | B18: 0.1 | D18: ≈ 0,1× input (giảm 90%)
A19: Số lượt (turns) / job | B19: 6 | C19: lượt
A20: Token input CACHE ĐƯỢC / lượt | B20: 3000 | C20: token | D20: System prompt + KB + few-shot
A21: Token input FRESH / lượt | B21: 1000 | C21: token | D21: Câu hỏi khách + dữ liệu động
A22: Token output / lượt | B22: 300 | C22: token
A23: → Cache write / job | B23: =B20*B17/1000000 -> 0.00375
A24: → Cache read / job | B24: =(B19-1)*B20*B18/1000000 -> 0.0015
A25: → Input fresh / job | B25: =B19*B21*B15/1000000 -> 0.006
A26: → Output / job | B26: =B19*B22*B16/1000000 -> 0.009
A27: → LLM / job — CÓ prompt caching | B27: =SUM(B23:B26) -> 0.02025
A28: → LLM / job — KHÔNG cache | B28: =B19*(B20+B21)*B15/1000000+B26 -> 0.033
A29: → % tiết kiệm nhờ caching | B29: =IF(B28=0,0,1-B27/B28) -> 0.38636364 | D29: Đòn bẩy rẻ nhất bạn có
A30: Dùng Batch API? (1 = có, 0 = không) | B30: 0 | D30: Batch giảm 50% — chỉ khi job KHÔNG cần realtime
A31: → LLM / job sau Batch | B31: =B27*(1-B30*0.5) -> 0.02025
A33: S4. API — SPEECH (để 0 nếu sản phẩm không có thoại)
A34: Giá STT ($ / phút) | B34: 0 | D34: Deepgram streaming list $0,0077/phút
A35: Số phút audio / job | B35: 0 | C35: phút
A36: Giá TTS ($ / 1M ký tự) | B36: 0 | D36: ElevenLabs Flash $50 · Google Standard $4
A37: Số ký tự TTS / job | B37: 0 | C37: ký tự | D37: ≈ 900 ký tự cho mỗi phút bot nói
A38: → Speech / job | B38: =B34*B35+B36*B37/1000000 -> 0
A40: S5. INFRA
A41: Infra / job ($) | B41: 0.008 | D41: Giả định vector DB + embeddings + logs + storage
A42: Telephony ($ / phút) | B42: 0 | D42: Không có thoại/telephony trong MVP text-only -> chi phí telephony = 0 có lý do.
A43: → Infra / job | B43: =B41+B42*B35 -> 0.008
A45: S6. RETRY
A46: Tỷ lệ job phải chạy lại | B46: 0.1 | D46: ĐỪNG để 0%. Thực tế 5–10% là bình thường
...

Sheet 2_Pricing
A1: TAB 2 — PRICING SANITY CHECK
A2: Trạm 3. Cost/Job tự lấy từ tab 1. Bạn điền giá bán và các con số neo giá.
A4: GIÁ SÀN | G4: HYBRID ECONOMICS — nguồn duy nhất cho phí nền + phí usage
A5: Cost/Job (từ tab 1_Cost_Job) | B5: ='1_Cost_Job'!B66 -> 0.075294872 | C5: $/job | G5: Phí nền $/shop/tháng [GIẢ ĐỊNH] | H5: 29
A6: Hệ số an toàn tối thiểu | B6: 3 | C6: × | D6: Giá bán ≥ 3 × Cost/Job | G6: Phí theo ticket resolved $ [GIẢ ĐỊNH] | H6: 0.23
A7: → GIÁ SÀN | B7: =B5*B6 -> 0.22588462 | C7: $/job | G7: Ticket completed / tháng (giả định) | H7: ='1_Cost_Job'!B11 -> 650
G8: Revenue nền + usage / tháng | H8: =H5+H6*H7 -> 178.5
A9: GIÁ TRẦN — NEO THEO THỨ KHÁCH ĐANG CHI | G9: COGS / tháng (loại overhead) | H9: ='1_Cost_Job'!B62+'1_Cost_Job'!B63 -> 48.941667
A10: Giá trị khách tiết kiệm được / tháng ($) | B10: 850 | D10: GIẢ ĐỊNH cần xác minh: $850/tháng giá trị thời gian/hậu mãi/giảm chi phí; chưa có phỏng vấn hoặc ROI. | G10: Gross margin BLENDED — toàn gói | H10: =IF(H8=0,0,1-H9/H8) -> 0.72581699
A11: Số job / tháng của 1 khách | B11: ='1_Cost_Job'!B11 -> 650 | C11: job | G11: ARPU / tháng | H11: =H8 -> 178.5
A12: → Trần theo giá trị — mức 10% | B12: =IF(B11=0,0,B10*0.1/B11) -> 0.13076923 | C12: $/job | G12: Giá hiệu dụng / completed job | H12: =IF(H7=0,0,H8/H7) -> 0.27461538
A13: → Trần theo giá trị — mức 25% | B13: =IF(B11=0,0,B10*0.25/B11) -> 0.32692308 | C13: $/job | G13: Overhead R&D/sales / tháng (không vào GM) | H13: ='1_Cost_Job'!B64 -> 40
A14: Lương / tháng của vị trí bị thay ($) | B14: 450 | D14: GIẢ ĐỊNH lương $450/tháng; giá không neo theo ChatGPT $20. | G14: Contribution sau overhead / tháng | H14: =H8-H9-H13 -> 89.558333
A15: → Trần theo nhân công — mức 50% | B15: =IF(B11=0,0,B14*0.5/B11) -> 0.34615385 | C15: $/job | G15: GM nếu containment=50% | H15: =IF(H5+H6*'1_Cost_Job'!B9*0.5=0,0,1-('1_Cost_Job'!B9*($B$29+$B$30+$B$31*(1-0.5)))/(H5+H6*'1_Cost_Job'!B9*0.5)) -> 0.66012731
A16: → Trần theo nhân công — mức 70% | B16: =IF(B11=0,0,B14*0.7/B11) -> 0.48461538 | C16: $/job | G16: Điểm gãy GM <50%: containment | H16: =MAX(0,('1_Cost_Job'!B9*($B$29+$B$30+$B$31)-(1-0.5)*H5)/('1_Cost_Job'!B9*((1-0.5)*H6+$B$31))) -> 0.29949275
G17: GM tại containment giả định | H17: =H10 -> 0.72581699
A18: GIÁ BÁN CỦA BẠN | G18: Tỷ lệ phí nền trong doanh thu | H18: =IF(H8=0,0,H5/H8) -> 0.16246499
A19: ★ Giá bán đề xuất ($ / job) | B19: =H12 -> 0.27461538 | C19: $/job | D19: B19 = giá hiệu dụng bình quân / resolved job ($0.2746), KHÔNG phải mức khách trực tiếp thanh toán. Thu phí giả định: $29/shop/tháng (H5) + $0.23/resolution (H6); chỉ pilot mô phỏng cho tới khi có Eval và quy định dispute. | G19: Doanh thu / giá trị khách tiết kiệm | H19: =IF(B10=0,0,H8/B10) -> 0.21
A20: → Bội số so với Cost/Job | B20: =IF(B5=0,0,B19/B5) -> 3.647199
A21: → GROSS MARGIN | B21: =H10 -> 0.72581699 | D21: GM 72.6% từ toàn bộ doanh thu Hybrid giả định, chi phí COGS API + Infra + Retry + QA. Overhead $40 là chi phí ngoài GM; contribution sau overhead tính tại H14. | G21: KIỂM SOÁT: không trộn GM usage-only với blended
A22: → Đèn: bội số ≥ 3? | B22: =IF(B20>=B6,"OK — ĐẠT","KHÔNG ĐẠT — quay lại tab 1") -> OK — ĐẠT | G22: Chỉ bán outcome sau Eval; hợp đồng chưa kích hoạt
A23: → Đèn: Gross Margin | B23: =IF(B21>=0.6,"OK — AN TOÀN (≥60%)",IF(B21>=0.5,"CẢNH BÁO (50–60%)","NGUY HIỂM (<50%)")) -> OK — AN TOÀN (≥60%) | G23: Cửa sổ reopen 24h chỉ là giả định, không benchmark
A24: → Đèn: GM có cao bất thường? | B24: =IF(B21>0.85,"NGHI NGỜ — nhiều khả năng bạn quên một khoản chi phí","OK") -> OK | G24: Giá API kiểm 08/10/2026; giá bán giả định
A25: → Giá bán nằm trong vùng neo? | B25: =IF(AND(B19>=B7,B19<=MAX(B13,B16)),"OK — trong vùng giá bán","XEM LẠI — ngoài vùng giá sàn/trần") -> OK — trong vùng giá bán | G25: Nếu containment=0: phí nền vẫn thu, job=0 (không dùng Cost/Job)
A27: MINIMUM CONTAINMENT TO REACH TARGET 60% GROSS MARGIN
A28: Ký hiệu: v = chi phí biến đổi / job thử · q = QA / job thử · e = chi phí 1 ca escalate
A29: v — chi phí biến đổi / job thử | B29: ='1_Cost_Job'!B31+'1_Cost_Job'!B38+'1_Cost_Job'!B43+'1_Cost_Job'!B47 -> 0.030275
A30: q — QA nội bộ / job thử | B30: ='1_Cost_Job'!B51*('1_Cost_Job'!B52/60)*'1_Cost_Job'!B50 -> 0.018666667
A31: e — chi phí 1 ca escalate | B31: =IF('1_Cost_Job'!B6="B",('1_Cost_Job'!B53/60)*'1_Cost_Job'!B50,0) -> 0
A32: Gross Margin mục tiêu | B32: 0.6
A33: ★ Containment tối thiểu cần đạt | B33: =MAX(0,('1_Cost_Job'!B9*(B29+B30+B31)-(1-B32)*H5)/('1_Cost_Job'!B9*((1-B32)*H6+B31))) -> 0.40588768 | D33: 40.6% là containment tối thiểu để GM >=60%, KHÔNG phải điểm hòa vốn lợi nhuận 0; hiện chỉ là mô phỏng (65% chưa có Eval).
A34: Containment hiện tại (từ tab 1) | B34: ='1_Cost_Job'!B10 -> 0.65
A35: → Kết luận | B35: =IF(B34>=B33,"ĐẠT — mô hình có lãi lành mạnh","CHƯA ĐẠT — phải tăng containment, tăng giá, hoặc đổi biến thể HITL") -> ĐẠT — mô hình có lãi lành mạnh
A37: SENSITIVITY — mô hình gãy ở đâu?
A38: Containment | B38: Cost/Job | C38: Gross Margin | D38: Đánh giá
A39: 0.5 | B39: =IF(A39=0,0,($B$29+$B$30+$B$31*(1-A39))/A39) -> 0.097883333 | C39: 0.66012731 | D39: =IF(C39>=0.6,"An toàn",IF(C39>=0.5,"Cảnh báo","Nguy hiểm")) -> An toàn
A40: 0.6 | B40: =IF(A40=0,0,($B$29+$B$30+$B$31*(1-A40))/A40) -> 0.081569444 | C40: 0.70693613 | D40: =IF(C40>=0.6,"An toàn",IF(C40>=0.5,"Cảnh báo","Nguy hiểm")) -> An toàn
A41: 0.7 | B41: =IF(A41=0,0,($B$29+$B$30+$B$31*(1-A41))/A41) -> 0.069916667 | C41: 0.74241228 | D41: =IF(C41>=0.6,"An toàn",IF(C41>=0.5,"Cảnh báo","Nguy hiểm")) -> An toàn
A42: 0.8 | B42: =IF(A42=0,0,($B$29+$B$30+$B$31*(1-A42))/A42) -> 0.061177083 | C42: 0.77022692 | D42: =IF(C42>=0.6,"An toàn",IF(C42>=0.5,"Cảnh báo","Nguy hiểm")) -> An toàn
A43: 0.9 | B43: =IF(A43=0,0,($B$29+$B$30+$B$31*(1-A43))/A43) -> 0.05437963 | C43: 0.79262006 | D43: =IF(C43>=0.6,"An toàn",IF(C43>=0.5,"Cảnh báo","Nguy hiểm")) -> An toàn
...

Sheet 3_Value_Metric
A1: TAB 3 — VALUE METRIC SCORECARD
A2: Trạm 2. Chấm 0 / 1 / 2 điểm cho mỗi câu, theo THỰC TẾ HÔM NAY.
A4: A. ATTRIBUTION — bạn đo được kết quả là do AI tạo ra không?
A5: 1. Tôi có log đầy đủ mỗi job AI xử lý, gắn được với kết quả cuối cùng | B5: 0
A6: 2. Tôi có bộ eval đo được tỷ lệ AI làm đúng, có số liệu | B6: 0
A7: 3. Khách hàng đồng ý với cách tôi định nghĩa 'thành công' của một job | B7: 0
A8: 4. Tôi phân biệt được kết quả do AI tạo ra với kết quả do yếu tố khác | B8: 0
A9: 5. Tôi viết được định nghĩa chặt như Intercom: cái gì tính tiền, cái gì không | B9: 1
A10: → ĐIỂM ATTRIBUTION (tối đa 10) | B10: =SUM(B5:B9) -> 1
A12: B. AUTONOMY — AI tự chạy hay cần người?
A13: 1. AI hoàn thành job từ đầu đến cuối, không cần người bấm nút giữa chừng | B13: 0
A14: 2. Job chạy được ngoài giờ hành chính mà không ai trực | B14: 0
A15: 3. Khi AI không chắc, nó tự chuyển tiếp đúng chỗ — không cần người phân loại | B15: 0
A16: 4. Tỷ lệ ca phải có người can thiệp dưới 20% | B16: 0
A17: 5. Người vận hành chỉ kiểm tra mẫu (QA), không xử lý từng ca | B17: 0
A18: → ĐIỂM AUTONOMY (tối đa 10) | B18: =SUM(B13:B17) -> 0
A20: GỢI Ý CỦA MODEL
A21: → Value Metric gợi ý | B21: =IF(AND(B10>=7,B18>=7),"OUTCOME",IF(AND(B10>=7,B18<7),"USAGE",IF(AND(B10<7,B18>=7),"USAGE (an toàn)","SEAT hoặc HYBRID"))) -> SEAT hoặc HYBRID
A22: Ngưỡng 7/10 là quy ước của bài tập, không phải chuẩn ngành — dùng để buộc bạn ra quyết định, không phải để thay bạn quyết định.
A24: BENCHMARK NGƯỢC — 2 sản phẩm thật cùng loại job
A25: Tên sản phẩm | B25: Value Metric | C25: Giá công bố | D25: Link nguồn
A26: Intercom Fin | B26: Outcome — resolution | C26: $0.99 / resolution | D26: https://fin.ai/pricing/
A27: Zendesk AI Agents | B27: Outcome — automated resolution | C27: $1.50/resolution committed; $2 pay-as-you-go (US pricing, kiểm 08/10/2026) | D27: https://www.zendesk.com/pricing/
A29: QUYẾT ĐỊNH CUỐI
A30: Value Metric tôi chọn | B30: HYBRID giả thuyết: $29 phí nền + usage pilot; mức $0.23/ticket verified là giá mục tiêu có điều kiện Eval, CHƯA triển khai outcome billing.
A31: Nếu KHÁC gợi ý — lý do thị trường là gì? | B31: Attribution 1/10 và Autonomy 0/10 đều là chấm giả định pre-MVP; chưa có eval. Trong pilot ưu tiên đo usage có giới hạn chi phí, chưa phát hóa đơn outcome.
A32: Decision Note — câu 1: tôi chọn đơn vị nào? | B32: Override thị trường: $29 nền chi cho KB, dashboard và hỗ trợ onboarding; khách SME cần dự báo ngân sách. $0.23/verified resolution chỉ được triển khai khi quy tắc dispute + eval đã được xác nhận.
A33: Decision Note — câu 2: bằng chứng Attribution / Autonomy? | B33: Attribution 1/10 (chỉ có định nghĩa job); Autonomy 0/10; chưa có log, khách, eval hoặc demo.
A34: Decision Note — câu 3: mô hình này lỗ trong tình huống nào? | B34: Rủi ro: ticket reopen, traffic tăng, tranh chấp attribution; giai đoạn đầu chỉ báo giá/pilot giả định, hợp đồng sau eval.

Sheet 4_Channel_Fit
A1: TAB 4 — CHANNEL FIT & AFFORDABILITY TEST
A2: Trạm 4. Chọn ĐÚNG 1 kênh cho 90 ngày đầu — và chứng minh bằng số.
A4: A. NGÂN SÁCH CAC — bạn nuôi nổi kênh nào? | G4: PLG CAC — GIẢ ĐỊNH FUNNEL TEST / THÁNG
A5: ARPU / tháng ($) | B5: ='2_Pricing'!H11 -> 178.5 | G5: Visitor đủ điều kiện | H5: 800
A6: Gross Margin (từ tab 2_Pricing) | B6: ='2_Pricing'!B21 -> 0.72581699 | G6: Visitor → sign-up | H6: 0.08
A7: Phân khúc (SMB / Mid / Enterprise) | B7: SMB | G7: Sign-up → kích hoạt shop | H7: 0.25
A8: → CAC payback cho phép (tháng) | B8: =IF(B7="SMB",12,IF(B7="Mid",18,24)) -> 12 | C8: tháng | D8: Bessemer, Scaling to $100M (2024) | G8: Kích hoạt → paid shop | H8: 0.25
A9: ★ NGÂN SÁCH CAC / khách | B9: =B5*B6*B8 -> 1554.7 | D9: ARPU × GM × số tháng payback | G9: Paid shops / tháng | H9: =H5*H6*H7*H8 -> 4
A10: → ACV (giá trị hợp đồng / năm) | B10: =B5*12 -> 2142 | G10: Acquisition spend $/tháng | H10: 240
G11: Chi phí onboarding + support trial $/tháng | H11: 80
A12: B. SALES VIABILITY — một AE phải chốt bao nhiêu deal? | G12: CAC PLG ƯỚC TÍNH / khách | H12: =IF(H9<1,NA(),(H10+H11)/H9) -> 80
A13: Quota / AE / năm ($) | B13: 500000 | D13: Giả định gốc của Tunguz (2016) — thay bằng số thị trường bạn | G13: CAC budget / PLG CAC | H13: =IFERROR(B9/H12,0) -> 19.43375
A14: Số ngày làm việc / năm | B14: 250 | C14: ngày | G14: Gate: PLG CAC ≤ budget? | H14: =IFERROR(IF(H12<=B9,"PASS hypothesis","FAIL hypothesis"),"NO DATA") -> PASS hypothesis
A15: → Số deal / AE / năm | B15: =IF(B10=0,0,B13/B10) -> 233.4267 | G15: Nguồn: toàn bộ là kịch bản, KHÔNG phải thực tế
A16: ★ Số deal / AE / NGÀY | B16: =IF(B14=0,0,B15/B14) -> 0.93370682 | C16: deal/ngày | G16: Nếu <1 paid shop thì CAC undefined; không diễn giải là 0
A17: → Kết luận Sales-Led | B17: =IF(B16<=1,"KHẢ THI về mặt số học","BẤT KHẢ THI — ACV quá thấp để nuôi sales rep") -> KHẢ THI về mặt số học | D17: Deals/day is mechanically <=1, but customer acquisition cost makes rep-led unaffordable. | G17: Kênh duy nhất trong 90 ngày: PLG
G18: Đầu mối inbound: demo sandbox, chưa khẳng định Zalo approved
A19: C. ĐỐI CHIẾU CAC THỰC TẾ CỦA MOTION CÓ SALES
A20: Cost per opportunity ($) | B20: 6300 | D20: ICONIQ 2026 theo phân khúc: $6.300 · $8.000 · $11.200
A21: Win rate | B21: 0.25
A22: → CAC thực tế ước tính / khách | B22: =IF(B21=0,0,B20/B21) -> 25200
A23: ★ Lệch bao nhiêu lần so với ngân sách CAC? | B23: =IF(B9=0,0,B22/B9) -> 16.208915 | D23: Đây là bằng chứng chọn kênh của bạn
A24: → Kết luận | B24: =IF(B23<=1,"Motion có sales KHẢ THI",IF(B23<=3,"Căng — cần tăng giá hoặc giảm chi phí bán hàng","KHÔNG KHẢ THI — đi PLG hoặc Partner-Led")) -> KHÔNG KHẢ THI — đi PLG hoặc Partner-Led
A26: D. CHẤM ĐIỂM 3 KÊNH (1 = rất kém, 5 = rất tốt)
A27: Tiêu chí | B27: PLG | C27: Sales-Led | D27: Partner-Led
A28: 1. Ngân sách CAC của tôi nuôi nổi kênh này | B28: 4 | C28: 1 | D28: 2
A29: 2. Khách hàng mục tiêu thực sự mua theo cách này | B29: 3 | C29: 3 | D29: 1
A30: 3. Đội hiện tại có năng lực chạy kênh này ngay | B30: 3 | C30: 2 | D30: 1
A31: 4. Tôi tiếp cận được điểm nhúng / partner trong 30 ngày | B31: 3 | C31: 2 | D31: 1
A32: 5. Kênh này đưa tôi đến ĐÚNG Pain Moment | B32: 4 | C32: 4 | D32: 2
A33: 6. Tôi đo được hiệu quả trong vòng 90 ngày | B33: 4 | C33: 3 | D33: 2
A34: → TỔNG ĐIỂM | B34: =SUM(B28:B33) -> 21 | C34: =SUM(C28:C33) -> 15 | D34: =SUM(D28:D33) -> 9
A35: → Kênh điểm cao nhất | B35: =IF(AND(B34>=C34,B34>=D34),"PLG",IF(C34>=D34,"Sales-Led","Partner-Led")) -> PLG
A37: E. CHỐT KÊNH
A38: ★ Kênh tôi chọn cho 90 ngày đầu | B38: PLG | D38: ĐÚNG 1 kênh. Chọn 2 kênh trở lên bị trừ điểm.
A39: Nếu Partner-Led: TÊN CÔNG TY partner | B39: Không áp dụng — không chọn Partner-Led | D39: 'Các nền tảng trong ngành' = chưa có kênh
A40: Đã nói chuyện với họ chưa? (Rồi / Chưa) | B40: Chưa
A41: Bạn mang lại giá trị gì cho partner? | B41: Chưa có partner; không hứa tích hợp đối tác chưa ký
A42: Nếu rơi vào vùng không khả thi — lối thoát nào? | B42: PLG giả thuyết vì rep-led benchmark $25,200/CAC cao hơn ngân sách; không có partner đã ký. Gate PLG CAC $80 (chỉ mô phỏng); thất bại nếu <4 paid/shop hoặc CAC > budget. 15 interview là research, không tính là kênh Sales-Led. | D42: PLG is a single-channel RESEARCH HYPOTHESIS. Simulated CAC is not observed; Zalo OA permissions unknown.

Sheet 5_90Day_Plan
A1: TAB 5 — PAIN MOMENT · 90-DAY PLAN · EVIDENCE PACK
A2: Trạm 5 và Trạm 6.
A4: A. PAIN MOMENT — phải đủ 3 phần
A5: MẤY GIỜ khách đau nhất? | B5: 20:00 (giả thuyết, xác minh phỏng vấn)
A6: Lúc đó họ ĐANG LÀM GÌ? | B6: Chủ shop đang trả lời 20+ câu lặp về đơn / vận chuyển
A7: Họ đang DÙNG APP / KÊNH NÀO? | B7: Zalo Official Account (kịch bản; cần xác minh API)
A8: → Điểm nhúng cụ thể của bạn | B8: Luồng chat Zalo OA qua webhook/official API sau khi được phê duyệt | D8: Một bề mặt tích hợp có tên, không phải 'website của chúng tôi'
A10: B. 90-DAY PLAN
B11: THÁNG 1 — Học | C11: THÁNG 2–3 — Đòn bẩy | D11: THÁNG 4+ — Mở rộng
A12: Kênh sử dụng | B12: PLG | C12: PLG | D12: PLG
A13: Mục tiêu số khách | B13: 5 shop thiết kế đồng hành; 0 cam kết trả tiền | C13: 10 shop kích hoạt, 3 pilot có thể trả phí | D13: 30 shop nếu đạt gate pilot
A14: Việc cụ thể 1 | B14: 15 phỏng vấn, xác thực volume + workflow | C14: Đưa MVP sandbox, đo ticket outcome | D14: Tối ưu onboarding và tích hợp
A15: Việc cụ thể 2 | B15: Thiết kế Job / policy KB / escalation | C15: Thử nghiệm phí $29 + $0.23/ticket | D15: Mở thêm một vertical shop nếu ROI dương
A16: Việc cụ thể 3 | B16: Thu 100 hội thoại giả lập, có đồng ý | C16: 1000+ ticket pilot đã gắn nhãn | D16: Giám sát lỗi và chi phí theo cohort
A17: KPI đo được | B17: 15 interview + 5 shops đồng thiết kế + 100 tình huống eval (TARGET) | C17: 10 shop kích hoạt; 3 pilot mục tiêu; >=60% containment chỉ nếu đo đúng | D17: >=60% blended GM, PLG CAC <= budget, payback <12 tháng (GATE)
A18: Người chịu trách nhiệm | B18: Chủ dự án: Bùi Thị Ngọc Trân (cá nhân; tự chịu trách nhiệm nghiên cứu và điều phối các tác vụ kỹ thuật dự kiến) | C18: Chủ dự án: Bùi Thị Ngọc Trân (chưa có Tech Lead hay khách thử nghiệm; chỉ triển khai khi đủ điều kiện) | D18: Chủ dự án: Bùi Thị Ngọc Trân (quyết định mở rộng sau khi kiểm chứng)
A19: Tháng 1 là giai đoạn HỌC, không phải scale. Kế hoạch 'tháng 1 lấy 200 khách ở 5 ngành' là kế hoạch chưa ai từng thử làm.
A21: C. EVIDENCE PACK — 3 tài sản bán hàng
A22: Tài sản | B22: Đã có? (Rồi/Chưa) | C22: Nội dung 1 câu — hoặc việc cần làm | D22: Người phụ trách · Deadline
A23: 1. Eval Results | B23: CHƯA CÓ — cần tạo bộ eval | C23: Eval 100 case phân tầng 4 intent; accuracy, unsupported claim, escalation, 24h-reopen, audit sampling | D23: Bùi Thị Ngọc Trân · deadline 31/10/2026 (kế hoạch, chưa có Eval)
A24: 2. Risk Checklist | B24: CHƯA CÓ — cần procurement Q&A | C24: Q&A có trích tài liệu thực tế nhà cung cấp: train-data, retention, DPA, export/delete, thất bại & fallback | D24: Bùi Thị Ngọc Trân · deadline 15/11/2026 (Q&A dạng draft; cần đối chiếu điều khoản DPA/retention)
A25: 3. Pilot Report | B25: CHƯA CÓ — cần thử pilot; không giả định hợp đồng | C25: Pilot 4 tuần tại 3 shop CÓ CONSENT; báo cáo 1000+ ticket, thời gian tiết kiệm thực, CAC, invoice (nếu có) | D25: Bùi Thị Ngọc Trân · deadline 08/01/2027 (pilot chưa thực hiện)
A26: Ô nào CHƯA CÓ thì ghi deadline — đừng bỏ trống. Thành thật về khoảng trống được điểm cao hơn bịa nội dung.
A28: D. BÀI TEST NGƯỜI LẠ — nhóm khác đọc One-Pager trong 2 phút | B28: CHƯA — lên lịch người đọc độc lập; không giả là đã đánh giá
A29: Họ trả lời được: bán gì, cho ai, tính tiền theo đơn vị nào? (Được/Không) | B29: CHƯA — lên lịch người đọc độc lập; không giả là đã đánh giá
A30: Họ trả lời được: có lãi trên mỗi đơn vị không, số nào chứng minh? (Được/Không) | B30: CHƯA TEST — mục tiêu kiểm thử độc lập; không công nhận đã PASS
A31: Họ trả lời được: tiếp cận khách qua đâu, vì sao kênh đó? (Được/Không) | B31: CHƯA — lên lịch người đọc độc lập; không giả là đã đánh giá
A32: Số câu họ phải hỏi lại (mục tiêu ≤ 3) | B32: CHƯA ĐO; không coi là qua test

Sheet 6_Benchmarks
A1: TAB 6 — BENCHMARKS (CHỈ ĐỌC)
A2: Giá chốt ngày 26/08/2026. Dòng có ⏳ là GIÁ KHUYẾN MẠI CÓ HẠN — phải kiểm tra lại.
A3: NGÀY BẠN KIỂM TRA LẠI GIÁ | B3: 2026-10-08 | D3: Bắt buộc điền — Rubric có chấm mục này
A5: Nhóm | B5: Mục | C5: Giá | D5: Đơn vị | E5: Nguồn
A6: LLM | B6: Claude Opus 5 — input / output | C6: 5,00 / 25,00 | D6: $ / 1M token | E6: platform.claude.com/docs/en/about-claude/pricing
A7: LLM | B7: Claude Sonnet 5 — input / output | C7: 2,00 / 10,00 | D7: $ / 1M token | E7: platform.claude.com/docs/en/about-claude/pricing
A8: LLM | B8: Claude Haiku 4.5 — input / output | C8: 1,00 / 5,00 | D8: $ / 1M token | E8: platform.claude.com/docs/en/about-claude/pricing
A9: LLM | B9: Claude — cache write 5' / cache read | C9: 1,25× / 0,10× input | D9: hệ số | E9: platform.claude.com/docs/en/about-claude/pricing
A10: LLM | B10: ⏳ OpenAI GPT-5.6 Sol — input / output | C10: 4,00 / 20,00 | D10: $ / 1M token | E10: developers.openai.com/api/docs/pricing (KM 21/08–21/11/2026; list 5,00/30,00)
A11: LLM | B11: OpenAI GPT-5.6 Luna — input / output | C11: 0,20 / 1,20 | D11: $ / 1M token | E11: developers.openai.com/api/docs/pricing
A12: LLM | B12: OpenAI — cached input / Batch API | C12: 10% input / −50% | D12: hệ số | E12: developers.openai.com/api/docs/pricing
A13: LLM | B13: Gemini 3.1 Pro — input / output (≤200k) | C13: 2,00 / 12,00 | D13: $ / 1M token | E13: ai.google.dev/gemini-api/docs/pricing
A14: LLM | B14: ⏳ Gemini 3.7 Flash — input / output | C14: 0,75 / 3,75 | D14: $ / 1M token | E14: ai.google.dev/gemini-api/docs/pricing (KM đến 31/12/2026; sau đó 1,50/7,50)
A15: STT | B15: Deepgram Nova-3 — pre-recorded | C15: 0,0043 | D15: $ / phút | E15: deepgram.com/pricing
A16: STT | B16: ⏳ Deepgram Nova-3 — streaming | C16: list 0,0077 · KM 0,0048 | D16: $ / phút | E16: deepgram.com/pricing — đang khuyến mại, kiểm tra lại
... A41: Benchmark | B41: ACV sàn cho inside sales | C41: ≈ 3.000 | D41: $ / năm | E41: Tomasz Tunguz (2016) — có kèm giả định để tính lại
A43: Lưu ý: trang marketing của nhà cung cấp có thể hiển thị giá cũ hơn trang docs. Ưu tiên trang docs / pricing chính thức.
A44: Giá Claude Haiku 4.5 đối chiếu official model docs 08/10/2026; phần còn lại giữ benchmark template 26/08/2026, cần tái xác minh trước ký hợp đồng. | E44: https://platform.claude.com/docs/en/models/haiku-4-5/overview
A45: Intercom Fin $0.99/outcome và Zendesk $1.50 committed, $2 PAYG per automated resolution. Giá 08/10/2026; giá chưa phản ánh gói tổng / ưu đãi khác. | E45: https://www.zendesk.com/pricing/
